Workbook

Sheet Campaign Data
A1: NOMUHUB | META CAMPAIGNS 2026 - INPUT SHEET
A2: 2026 figures only, taken month by month from Meta Ads Manager so every date is exact. Blue cells are typed in, white cells calculate. The Dashboard reads rows 5 to 21.
A4: Campaign Name | B4: Start Date | C4: First Month | D4: Last Month | E4: Months Live | F4: Status | G4: Objective | H4: Allocated Budget (SAR) | I4: Actual Spend (SAR) | J4: Results | K4: Impressions | L4: Reach | M4: Purchases | N4: Budget Remaining (SAR) | O4: Budget Used % | P4: Cost per Result (SAR) | Q4: CPM (SAR) | R4: Frequency
A5: 2026 Nomuhup Carousell | B5: 46201 | C5: Jun 2026 | D5: Aug 2026 | E5: 3 | F5: Inactive | G5: Messages | I5: 7463.84 | J5: 393 | K5: 144735 | L5: 46736 | M5: 6 | N5: =IF(H5="","",H5-I5) | O5: =IFERROR(I5/H5,"") | P5: =IFERROR(I5/J5,"") -> 18.991959 | Q5: =IFERROR(I5/K5*1000,"") -> 51.569005 | R5: =IFERROR(K5/L5,"") -> 3.0968632
A6: retarget sales | B6: 46054 | C6: Feb 2026 | D6: Aug 2026 | E6: 4 | F6: Active | G6: Purchases | I6: 2206.83 | J6: 4 | K6: 58487 | L6: 14024 | M6: 4 | N6: =IF(H6="","",H6-I6) | O6: =IFERROR(I6/H6,"") | P6: =IFERROR(I6/J6,"") -> 551.7075 | Q6: =IFERROR(I6/K6*1000,"") -> 37.731975 | R6: =IFERROR(K6/L6,"") -> 4.1704934
A7: ZNZ Build MSG - 2026 | B7: 46019 | C7: Jan 2026 | D7: Jan 2026 | E7: 1 | F7: Inactive | G7: Messages | I7: 2160.47 | J7: 163 | K7: 227256 | L7: 89491 | M7: 2 | N7: =IF(H7="","",H7-I7) | O7: =IFERROR(I7/H7,"") | P7: =IFERROR(I7/J7,"") -> 13.254417 | Q7: =IFERROR(I7/K7*1000,"") -> 9.5067677 | R7: =IFERROR(K7/L7,"") -> 2.5394285
A8: Discount Code | B8: 45706 | C8: Jan 2026 | D8: Feb 2026 | E8: 2 | F8: Inactive | G8: Messages | I8: 2133.61 | J8: 149 | K8: 84544 | L8: 16660 | M8: 1 | N8: =IF(H8="","",H8-I8) | O8: =IFERROR(I8/H8,"") | P8: =IFERROR(I8/J8,"") -> 14.31953 | Q8: =IFERROR(I8/K8*1000,"") -> 25.236681 | R8: =IFERROR(K8/L8,"") -> 5.0746699
A9: Vietnam explore sales | B9: 46049 | C9: Jan 2026 | D9: Feb 2026 | E9: 2 | F9: Inactive | G9: Purchases | I9: 1687.16 | J9: 1 | K9: 119526 | L9: 42722 | M9: 1 | N9: =IF(H9="","",H9-I9) | O9: =IFERROR(I9/H9,"") | P9: =IFERROR(I9/J9,"") -> 1687.16 | Q9: =IFERROR(I9/K9*1000,"") -> 14.115423 | R9: =IFERROR(K9/L9,"") -> 2.7977623
A10: Vietnam Explore MSG - 2026 | B10: 46037 | C10: Jan 2026 | D10: Jan 2026 | E10: 1 | F10: Inactive | G10: Messages | I10: 1082.58 | J10: 19 | K10: 44551 | L10: 21901 | M10: 0 | N10: =IF(H10="","",H10-I10) | O10: =IFERROR(I10/H10,"") | P10: =IFERROR(I10/J10,"") -> 56.977895 | Q10: =IFERROR(I10/K10*1000,"") -> 24.299791 | R10: =IFERROR(K10/L10,"") -> 2.0341994
A11: Thailan Wellness MSG - 2026 | B11: 46019 | C11: Jan 2026 | D11: Jan 2026 | E11: 1 | F11: Inactive | G11: Messages | I11: 982.25 | J11: 46 | K11: 21744 | L11: 12295 | M11: 0 | N11: =IF(H11="","",H11-I11) | O11: =IFERROR(I11/H11,"") | P11: =IFERROR(I11/J11,"") -> 21.353261 | Q11: =IFERROR(I11/K11*1000,"") -> 45.173381 | R11: =IFERROR(K11/L11,"") -> 1.7685238
A12: Bali Explore Msgs CPO | B12: 46243 | C12: Aug 2026 | D12: Aug 2026 | E12: 1 | F12: Inactive | G12: Messages | I12: 589.51 | J12: 25 | K12: 15487 | L12: 8432 | M12: 0 | N12: =IF(H12="","",H12-I12) | O12: =IFERROR(I12/H12,"") | P12: =IFERROR(I12/J12,"") -> 23.5804 | Q12: =IFERROR(I12/K12*1000,"") -> 38.064829 | R12: =IFERROR(K12/L12,"") -> 1.8366935
A13: ZNZ Explore Msgs CPO | B13: 46243 | C13: Aug 2026 | D13: Aug 2026 | E13: 1 | F13: Inactive | G13: Messages | I13: 463.59 | J13: 17 | K13: 11464 | L13: 6277 | M13: 0 | N13: =IF(H13="","",H13-I13) | O13: =IFERROR(I13/H13,"") | P13: =IFERROR(I13/J13,"") -> 27.27 | Q13: =IFERROR(I13/K13*1000,"") -> 40.438765 | R13: =IFERROR(K13/L13,"") -> 1.8263502
A14: ZNZ Medical - 2 | B14: 45995 | C14: Jan 2026 | D14: Jan 2026 | E14: 1 | F14: Inactive | G14: Messages | I14: 306.55 | J14: 43 | K14: 34974 | L14: 26283 | M14: 0 | N14: =IF(H14="","",H14-I14) | O14: =IFERROR(I14/H14,"") | P14: =IFERROR(I14/J14,"") -> 7.1290698 | Q14: =IFERROR(I14/K14*1000,"") -> 8.7650826 | R14: =IFERROR(K14/L14,"") -> 1.33067
A15: ZNZ Build10% | B15: 46256 | C15: Aug 2026 | D15: Aug 2026 | E15: 1 | F15: Active | G15: Messages | I15: 61.15 | J15: 12 | K15: 3865 | L15: 2894 | M15: 0 | N15: =IF(H15="","",H15-I15) | O15: =IFERROR(I15/H15,"") | P15: =IFERROR(I15/J15,"") -> 5.0958333 | Q15: =IFERROR(I15/K15*1000,"") -> 15.821475 | R15: =IFERROR(K15/L15,"") -> 1.3355218
A16: Bali Explore 10% | B16: 46256 | C16: Aug 2026 | D16: Aug 2026 | E16: 1 | F16: Active | G16: Messages | I16: 57.98 | J16: 7 | K16: 2143 | L16: 1700 | M16: 0 | N16: =IF(H16="","",H16-I16) | O16: =IFERROR(I16/H16,"") | P16: =IFERROR(I16/J16,"") -> 8.2828571 | Q16: =IFERROR(I16/K16*1000,"") -> 27.05553 | R16: =IFERROR(K16/L16,"") -> 1.2605882
A17: Vietnam Explore 10% | B17: 46256 | C17: Aug 2026 | D17: Aug 2026 | E17: 1 | F17: Active | G17: Messages | I17: 55.44 | J17: 3 | K17: 3041 | L17: 2472 | M17: 0 | N17: =IF(H17="","",H17-I17) | O17: =IFERROR(I17/H17,"") | P17: =IFERROR(I17/J17,"") -> 18.48 | Q17: =IFERROR(I17/K17*1000,"") -> 18.230845 | R17: =IFERROR(K17/L17,"") -> 1.230178
N18: =IF(H18="","",H18-I18) | O18: =IFERROR(I18/H18,"") | P18: =IFERROR(I18/J18,"") | Q18: =IFERROR(I18/K18*1000,"") | R18: =IFERROR(K18/L18,"")
N19: =IF(H19="","",H19-I19) | O19: =IFERROR(I19/H19,"") | P19: =IFERROR(I19/J19,"") | Q19: =IFERROR(I19/K19*1000,"") | R19: =IFERROR(K19/L19,"")
N20: =IF(H20="","",H20-I20) | O20: =IFERROR(I20/H20,"") | P20: =IFERROR(I20/J20,"") | Q20: =IFERROR(I20/K20*1000,"") | R20: =IFERROR(K20/L20,"")
N21: =IF(H21="","",H21-I21) | O21: =IFERROR(I21/H21,"") | P21: =IFERROR(I21/J21,"") | Q21: =IFERROR(I21/K21*1000,"") | R21: =IFERROR(K21/L21,"")
A22: TOTAL / AVERAGE | H22: =SUM(H5:H21) -> 0 | I22: =SUM(I5:I21) -> 19250.96 | J22: =SUM(J5:J21) -> 882 | K22: =SUM(K5:K21) -> 771817 | L22: =SUM(L5:L21) -> 291887 | M22: =SUM(M5:M21) -> 14 | N22: =IF(H22=0,"",H22-I22) | O22: =IFERROR(I22/H22,"") | P22: =IFERROR(I22/J22,"") -> 21.826485 | Q22: =IFERROR(I22/K22*1000,"") -> 24.942389 | R22: =IFERROR(K22/L22,"") -> 2.6442322

Sheet Dashboard
B3: META ADS | NOMUHUB 2026 | I3: ="Campaigns live in 2026: "&COUNTA('Campaign Data'!A5:A21)&" | Earlier years on Previous Trips tab" -> Campaigns live in 2026: 13 | Earlier years on Previous Trips tab
B6: PERFORMANCE | J6: SPEND BY OBJECTIVE
B8: ALLOCATED BUDGET | D8: ACTUAL SPEND | F8: BUDGET REMAINING | H8: BUDGET USED
B9: ='Campaign Data'!H22 -> 0 | D9: ='Campaign Data'!I22 -> 19250.96 | F9: ='Campaign Data'!N22 | H9: ='Campaign Data'!O22
B11: RESULTS | D11: COST PER RESULT | F11: IMPRESSIONS | H11: REACH
B12: ='Campaign Data'!J22 -> 882 | D12: ='Campaign Data'!P22 -> 21.826485 | F12: ='Campaign Data'!K22 -> 771817 | H12: ='Campaign Data'!L22 -> 291887
B14: FREQUENCY | D14: CPM | F14: PURCHASES | H14: CAMPAIGNS
B15: ='Campaign Data'!R22 -> 2.6442322 | D15: ='Campaign Data'!Q22 -> 24.942389 | F15: ='Campaign Data'!M22 -> 14 | H15: =COUNTA('Campaign Data'!A5:A21) -> 13
B19: BUDGET vs ACTUAL SPEND | H19: RESULTS BY CAMPAIGN
B35: PERFORMANCE BY CAMPAIGN OBJECTIVE
B36: Campaign Objective | D36: Campaigns | E36: Allocated | F36: Spend | G36: Impressions | H36: CPM | I36: Reach | J36: Purchases | K36: Results | L36: Cost/Result | M36: % of Spend
B37: Messages | D37: =COUNTIF('Campaign Data'!$G$5:$G$21,$B37) -> 11 | E37: =SUMIF('Campaign Data'!$G$5:$G$21,$B37,'Campaign Data'!$H$5:$H$21) -> 0 | F37: =SUMIF('Campaign Data'!$G$5:$G$21,$B37,'Campaign Data'!$I$5:$I$21) -> 15356.97 | G37: =SUMIF('Campaign Data'!$G$5:$G$21,$B37,'Campaign Data'!$K$5:$K$21) -> 593804 | H37: =IFERROR(F37/G37*1000,"") -> 25.862018 | I37: =SUMIF('Campaign Data'!$G$5:$G$21,$B37,'Campaign Data'!$L$5:$L$21) -> 235141 | J37: =SUMIF('Campaign Data'!$G$5:$G$21,$B37,'Campaign Data'!$M$5:$M$21) -> 9 | K37: =SUMIF('Campaign Data'!$G$5:$G$21,$B37,'Campaign Data'!$J$5:$J$21) -> 877 | L37: =IFERROR(F37/K37,"") -> 17.510798 | M37: =IFERROR(F37/'Campaign Data'!$I$22,"") -> 0.79772489
B38: Purchases | D38: =COUNTIF('Campaign Data'!$G$5:$G$21,$B38) -> 2 | E38: =SUMIF('Campaign Data'!$G$5:$G$21,$B38,'Campaign Data'!$H$5:$H$21) -> 0 | F38: =SUMIF('Campaign Data'!$G$5:$G$21,$B38,'Campaign Data'!$I$5:$I$21) -> 3893.99 | G38: =SUMIF('Campaign Data'!$G$5:$G$21,$B38,'Campaign Data'!$K$5:$K$21) -> 178013 | H38: =IFERROR(F38/G38*1000,"") -> 21.874751 | I38: =SUMIF('Campaign Data'!$G$5:$G$21,$B38,'Campaign Data'!$L$5:$L$21) -> 56746 | J38: =SUMIF('Campaign Data'!$G$5:$G$21,$B38,'Campaign Data'!$M$5:$M$21) -> 5 | K38: =SUMIF('Campaign Data'!$G$5:$G$21,$B38,'Campaign Data'!$J$5:$J$21) -> 5 | L38: =IFERROR(F38/K38,"") -> 778.798 | M38: =IFERROR(F38/'Campaign Data'!$I$22,"") -> 0.20227511
B39: Leads | D39: =COUNTIF('Campaign Data'!$G$5:$G$21,$B39) -> 0 | E39: =SUMIF('Campaign Data'!$G$5:$G$21,$B39,'Campaign Data'!$H$5:$H$21) -> 0 | F39: =SUMIF('Campaign Data'!$G$5:$G$21,$B39,'Campaign Data'!$I$5:$I$21) -> 0 | G39: =SUMIF('Campaign Data'!$G$5:$G$21,$B39,'Campaign Data'!$K$5:$K$21) -> 0 | H39: =IFERROR(F39/G39*1000,"") | I39: =SUMIF('Campaign Data'!$G$5:$G$21,$B39,'Campaign Data'!$L$5:$L$21) -> 0 | J39: =SUMIF('Campaign Data'!$G$5:$G$21,$B39,'Campaign Data'!$M$5:$M$21) -> 0 | K39: =SUMIF('Campaign Data'!$G$5:$G$21,$B39,'Campaign Data'!$J$5:$J$21) -> 0 | L39: =IFERROR(F39/K39,"") | M39: =IFERROR(F39/'Campaign Data'!$I$22,"") -> 0
B40: Link Clicks | D40: =COUNTIF('Campaign Data'!$G$5:$G$21,$B40) -> 0 | E40: =SUMIF('Campaign Data'!$G$5:$G$21,$B40,'Campaign Data'!$H$5:$H$21) -> 0 | F40: =SUMIF('Campaign Data'!$G$5:$G$21,$B40,'Campaign Data'!$I$5:$I$21) -> 0 | G40: =SUMIF('Campaign Data'!$G$5:$G$21,$B40,'Campaign Data'!$K$5:$K$21) -> 0 | H40: =IFERROR(F40/G40*1000,"") | I40: =SUMIF('Campaign Data'!$G$5:$G$21,$B40,'Campaign Data'!$L$5:$L$21) -> 0 | J40: =SUMIF('Campaign Data'!$G$5:$G$21,$B40,'Campaign Data'!$M$5:$M$21) -> 0 | K40: =SUMIF('Campaign Data'!$G$5:$G$21,$B40,'Campaign Data'!$J$5:$J$21) -> 0 | L40: =IFERROR(F40/K40,"") | M40: =IFERROR(F40/'Campaign Data'!$I$22,"") -> 0
B41: Reach | D41: =COUNTIF('Campaign Data'!$G$5:$G$21,$B41) -> 0 | E41: =SUMIF('Campaign Data'!$G$5:$G$21,$B41,'Campaign Data'!$H$5:$H$21) -> 0 | F41: =SUMIF('Campaign Data'!$G$5:$G$21,$B41,'Campaign Data'!$I$5:$I$21) -> 0 | G41: =SUMIF('Campaign Data'!$G$5:$G$21,$B41,'Campaign Data'!$K$5:$K$21) -> 0 | H41: =IFERROR(F41/G41*1000,"") | I41: =SUMIF('Campaign Data'!$G$5:$G$21,$B41,'Campaign Data'!$L$5:$L$21) -> 0 | J41: =SUMIF('Campaign Data'!$G$5:$G$21,$B41,'Campaign Data'!$M$5:$M$21) -> 0 | K41: =SUMIF('Campaign Data'!$G$5:$G$21,$B41,'Campaign Data'!$J$5:$J$21) -> 0 | L41: =IFERROR(F41/K41,"") | M41: =IFERROR(F41/'Campaign Data'!$I$22,"") -> 0
B42: Custom Conversion | D42: =COUNTIF('Campaign Data'!$G$5:$G$21,$B42) -> 0 | E42: =SUMIF('Campaign Data'!$G$5:$G$21,$B42,'Campaign Data'!$H$5:$H$21) -> 0 | F42: =SUMIF('Campaign Data'!$G$5:$G$21,$B42,'Campaign Data'!$I$5:$I$21) -> 0 | G42: =SUMIF('Campaign Data'!$G$5:$G$21,$B42,'Campaign Data'!$K$5:$K$21) -> 0 | H42: =IFERROR(F42/G42*1000,"") | I42: =SUMIF('Campaign Data'!$G$5:$G$21,$B42,'Campaign Data'!$L$5:$L$21) -> 0 | J42: =SUMIF('Campaign Data'!$G$5:$G$21,$B42,'Campaign Data'!$M$5:$M$21) -> 0 | K42: =SUMIF('Campaign Data'!$G$5:$G$21,$B42,'Campaign Data'!$J$5:$J$21) -> 0 | L42: =IFERROR(F42/K42,"") | M42: =IFERROR(F42/'Campaign Data'!$I$22,"") -> 0
B43: ALL OBJECTIVES | D43: =SUM(D37:D42) -> 13 | E43: =SUM(E37:E42) -> 0 | F43: =SUM(F37:F42) -> 19250.96 | G43: =SUM(G37:G42) -> 771817 | H43: =IFERROR(F43/G43*1000,"") -> 24.942389 | I43: =SUM(I37:I42) -> 291887 | J43: =SUM(J37:J42) -> 14 | K43: =SUM(K37:K42) -> 882 | L43: =IFERROR(F43/K43,"") -> 21.826485 | M43: =IFERROR(F43/'Campaign Data'!$I$22,"") -> 1
B46: All figures in SAR and cover 2026 only, month by month from Meta. Update the Campaign Data tab, this page refreshes on its own.

Sheet Previous Trips
B2: NOMUHUB | PREVIOUS TRIPS - FULL CAMPAIGN ARCHIVE BY YEAR
B5: One row per campaign per year, with the exact months it ran, taken from Meta's month by month delivery data across both NomuHub ad accounts. Reference only
B6: ROWS (CAMPAIGN x YEAR) | D6: TOTAL SPENT | F6: ROWS WITH SPEND | H6: TOTAL IMPRESSIONS | K6: TOTAL REACH | M6: TOTAL PURCHASES | O6: EXACT START DATES FOUND | Q6: USD to SAR RATE | T6: SPEND BY YEAR
B7: =COUNTA(B9:B156) -> 148 | D7: =SUM(L9:L156) -> 414246.19 | F7: =COUNTIF(L9:L156,">0") -> 103 | H7: =SUM(O9:O156) -> 69526460 | K7: =SUM(P9:P156) -> 24471044 | M7: =SUM(Q9:Q156) -> 66 | O7: =COUNT(S9:S156) -> 102 | Q7: 3.75 | T7: amber years = figures purged by Meta
B8: Campaign Name | C8: Year | D8: First Month | E8: Last Month | F8: Months Live | G8: Ad Account | H8: Status | I8: Objective | J8: Spend (orig) | K8: Cur | L8: Spend (SAR) | M8: Results | N8: Cost per Result (SAR) | O8: Impressions | P8: Reach | Q8: Purchases | R8: Date Source | S8: Campaign Start Date | T8: Year | U8: Spend (SAR) | V8: Campaigns
B9: Summer 2019 - New - Copy | C9: 2019 | D9: Purged by Meta | E9: Purged by Meta | G9: Nomuhub ad account | H9: Inactive | I9: No delivery | J9: 0 | K9: SAR | L9: =IF(K9="USD",J9*$Q$7,J9) -> 0 | N9: =IFERROR(L9/M9,"") | R9: Ran before Jul 2023, figures purged | S9: not in master file | T9: 2019 | U9: =SUMIF($C$9:$C$156,$T9,$L$9:$L$156) -> 0 | V9: =COUNTIF($C$9:$C$156,$T9) -> 4
B10: Morocco Summer 2019 campaign | C10: 2019 | D10: Purged by Meta | E10: Purged by Meta | G10: Nomuhub ad account | H10: Inactive | I10: No delivery | J10: 0 | K10: SAR | L10: =IF(K10="USD",J10*$Q$7,J10) -> 0 | N10: =IFERROR(L10/M10,"") | R10: Ran before Jul 2023, figures purged | S10: not in master file | T10: 2021 | U10: =SUMIF($C$9:$C$156,$T10,$L$9:$L$156) -> 0 | V10: =COUNTIF($C$9:$C$156,$T10) -> 6
B11: Zanzibar April 2019 | C11: 2019 | D11: Purged by Meta | E11: Purged by Meta | G11: Nomuhub ad account | H11: Inactive | I11: No delivery | J11: 0 | K11: SAR | L11: =IF(K11="USD",J11*$Q$7,J11) -> 0 | N11: =IFERROR(L11/M11,"") | R11: Ran before Jul 2023, figures purged | S11: not in master file | T11: 2022 | U11: =SUMIF($C$9:$C$156,$T11,$L$9:$L$156) -> 0 | V11: =COUNTIF($C$9:$C$156,$T11) -> 2
B12: Summer 2019 (first ad) | C12: 2019 | D12: Purged by Meta | E12: Purged by Meta | G12: Nomuhub ad account | H12: Inactive | I12: No delivery | J12: 0 | K12: SAR | L12: =IF(K12="USD",J12*$Q$7,J12) -> 0 | N12: =IFERROR(L12/M12,"") | R12: Ran before Jul 2023, figures purged | S12: not in master file | T12: 2023 | U12: =SUMIF($C$9:$C$156,$T12,$L$9:$L$156) -> 94094.42 | V12: =COUNTIF($C$9:$C$156,$T12) -> 18
B13: Retargeting_OCT_2021 | C13: 2021 | D13: Purged by Meta | E13: Purged by Meta | G13: Nomuhub ad account | H13: Archived | I13: No delivery | J13: 0 | K13: SAR | L13: =IF(K13="USD",J13*$Q$7,J13) -> 0 | N13: =IFERROR(L13/M13,"") | R13: Ran before Jul 2023, figures purged | S13: not in master file | T13: 2024 | U13: =SUMIF($C$9:$C$156,$T13,$L$9:$L$156) -> 191208.71 | V13: =COUNTIF($C$9:$C$156,$T13) -> 57
B14: Winter_GCCAudience25102021_conversions | C14: 2021 | D14: Purged by Meta | E14: Purged by Meta | G14: Nomuhub ad account | H14: Inactive | I14: No delivery | J14: 0 | K14: SAR | L14: =IF(K14="USD",J14*$Q$7,J14) -> 0 | N14: =IFERROR(L14/M14,"") | R14: Ran before Jul 2023, figures purged | S14: not in master file | T14: 2025 | U14: =SUMIF($C$9:$C$156,$T14,$L$9:$L$156) -> 128943.06 | V14: =COUNTIF($C$9:$C$156,$T14) -> 34
B15: GCCBroaderAudience_Septrip_2021 | C15: 2021 | D15: Purged by Meta | E15: Purged by Meta | G15: Nomuhub ad account | H15: Inactive | I15: No delivery | J15: 0 | K15: SAR | L15: =IF(K15="USD",J15*$Q$7,J15) -> 0 | N15: =IFERROR(L15/M15,"") | R15: Ran before Jul 2023, figures purged | S15: not in master file | T15: Never delivered | U15: =SUMIF($C$9:$C$156,$T15,$L$9:$L$156) -> 0 | V15: =COUNTIF($C$9:$C$156,$T15) -> 27
B16: PRO_GCCBroaderAudience18082021 | C16: 2021 | D16: Purged by Meta | E16: Purged by Meta | G16: Nomuhub ad account | H16: Inactive | I16: No delivery | J16: 0 | K16: SAR | L16: =IF(K16="USD",J16*$Q$7,J16) -> 0 | N16: =IFERROR(L16/M16,"") | R16: Ran before Jul 2023, figures purged | S16: not in master file
B17: Retargeting_sep_2021 | C17: 2021 | D17: Purged by Meta | E17: Purged by Meta | G17: Nomuhub ad account | H17: Inactive | I17: No delivery | J17: 0 | K17: SAR | L17: =IF(K17="USD",J17*$Q$7,J17) -> 0 | N17: =IFERROR(L17/M17,"") | R17: Ran before Jul 2023, figures purged | S17: not in master file
B18: RET_Websitevisitors,Videoviewers,Eanagers_SeptTrips 18082021 | C18: 2021 | D18: Purged by Meta | E18: Purged by Meta | G18: Nomuhub ad account | H18: Inactive | I18: No delivery | J18: 0 | K18: SAR | L18: =IF(K18="USD",J18*$Q$7,J18) -> 0 | N18: =IFERROR(L18/M18,"") | R18: Ran before Jul 2023, figures purged | S18: not in master file
B19: Summer_Campaign_2022_Traffic | C19: 2022 | D19: Purged by Meta | E19: Purged by Meta | G19: Nomuhub ad account | H19: Inactive | I19: No delivery | J19: 0 | K19: SAR | L19: =IF(K19="USD",J19*$Q$7,J19) -> 0 | N19: =IFERROR(L19/M19,"") | R19: Ran before Jul 2023, figures purged | S19: not in master file
B20: Retargeting_Reach_Winter2022 | C20: 2022 | D20: Purged by Meta | E20: Purged by Meta | G20: Nomuhub ad account | H20: Inactive | I20: Reach | J20: 0 | K20: SAR | L20: =IF(K20="USD",J20*$Q$7,J20) -> 0 | N20: =IFERROR(L20/M20,"") | R20: Ran before Jul 2023, figures purged | S20: not in master file
B21: August Sales Campaign 2023 | C21: 2023 | D21: Jul 2023 | E21: Oct 2023 | F21: 4 | G21: Nomuhub ad account | H21: Inactive | I21: Custom Conversion | J21: 42615.52 | K21: SAR | L21: =IF(K21="USD",J21*$Q$7,J21) -> 42615.52 | M21: 162411 | N21: =IFERROR(L21/M21,"") -> 0.26239306 | O21: 20231220 | P21: 5320895 | R21: Meta delivery data | S21: 45114
B22: Oct Nov Dec Leads Campaign 2023 | C22: 2023 | D22: Aug 2023 | E22: Nov 2023 | F22: 4 | G22: Nomuhub ad account | H22: Inactive | I22: Custom Conversion | J22: 20000 | K22: SAR | L22: =IF(K22="USD",J22*$Q$7,J22) -> 20000 | M22: 132874 | N22: =IFERROR(L22/M22,"") -> 0.15051854 | O22: 10731816 | P22: 2932405 | R22: Meta delivery data | S22: 45158
B23: Zanzibar_Leads_2023 | C23: 2023 | D23: Nov 2023 | E23: Dec 2023 | F23: 2 | G23: Nomuhub ad account | H23: Inactive | I23: Custom Conversion | J23: 9054.98 | K23: SAR | L23: =IF(K23="USD",J23*$Q$7,J23) -> 9054.98 | M23: 37115 | N23: =IFERROR(L23/M23,"") -> 0.2439709 | O23: 4609157 | P23: 1354502 | R23: Meta delivery data | S23: 45246
B24: Bali_Leads_2023 | C24: 2023 | D24: Nov 2023 | E24: Dec 2023 | F24: 2 | G24: Nomuhub ad account | H24: Inactive | I24: Custom Conversion | J24: 6419.79 | K24: SAR | L24: =IF(K24="USD",J24*$Q$7,J24) -> 6419.79 | M24: 37197 | N24: =IFERROR(L24/M24,"") -> 0.17258892 | O24: 3066398 | P24: 804440 | R24: Meta delivery data | S24: 45252
B25: Alula campaign 2023 | C25: 2023 | D25: Sep 2023 | E25: Oct 2023 | F25: 2 | G25: Nomuhub ad account | H25: Inactive | I25: Link Clicks | J25: 5625 | K25: SAR | L25: =IF(K25="USD",J25*$Q$7,J25) -> 5625 | M25: 58817 | N25: =IFERROR(L25/M25,"") -> 0.095635616 | O25: 1694913 | P25: 953620 | R25: Meta delivery data | S25: 45194
B26: Italy Blue Zone 2023 / Explore + Kenya | C26: 2023 | D26: Sep 2023 | E26: Oct 2023 | F26: 2 | G26: Nomuhub ad account | H26: Inactive | I26: Custom Conversion | J26: 2630.62 | K26: SAR | L26: =IF(K26="USD",J26*$Q$7,J26) -> 2630.62 | M26: 2599 | N26: =IFERROR(L26/M26,"") -> 1.0121662 | O26: 888041 | P26: 174599 | R26: Meta delivery data | S26: 45194
B27: SriLanka_Leads_2023 | C27: 2023 | D27: Nov 2023 | E27: Dec 2023 | F27: 2 | G27: Nomuhub ad account | H27: Inactive | I27: Custom Conversion | J27: 2199.17 | K27: SAR | L27: =IF(K27="USD",J27*$Q$7,J27) -> 2199.17 | M27: 11832 | N27: =IFERROR(L27/M27,"") -> 0.18586629 | O27: 1374077 | P27: 412394 | R27: Meta delivery data | S27: 45252
B28: ZNZ_Building_2023 | C28: 2023 | D28: Jul 2023 | E28: Aug 2023 | F28: 2 | G28: Nomuhub ad account | H28: Inactive | I28: Custom Conversion | J28: 1931.12 | K28: SAR | L28: =IF(K28="USD",J28*$Q$7,J28) -> 1931.12 | M28: 907 | N28: =IFERROR(L28/M28,"") -> 2.129129 | O28: 123605 | P28: 64110 | R28: Meta delivery data | S28: 45040
B29: Dooma_Awareness_2023 | C29: 2023 | D29: Sep 2023 | E29: Oct 2023 | F29: 2 | G29: Nomuhub ad account | H29: Inactive | I29: Reach | J29: 1500 | K29: SAR | L29: =IF(K29="USD",J29*$Q$7,J29) -> 1500 | M29: 555683 | N29: =IFERROR(L29/M29,"") -> 0.0026993808 | O29: 776137 | P29: 555683 | R29: Meta delivery data | S29: 45194
B30: Kenya_Sales_2023 | C30: 2023 | D30: Dec 2023 | E30: Dec 2023 | F30: 1 | G30: Nomuhub ad account | H30: Inactive | I30: Custom Conversion | J30: 1234.07 | K30: SAR | L30: =IF(K30="USD",J30*$Q$7,J30) -> 1234.07 | M30: 1284 | N30: =IFERROR(L30/M30,"") -> 0.96111371 | O30: 225410 | P30: 109148 | R30: Meta delivery data | S30: 45263
B31: Leads_AncientKingdoms_2023 | C31: 2023 | D31: Nov 2023 | E31: Nov 2023 | F31: 1 | G31: Nomuhub ad account | H31: Inactive | I31: Custom Conversion | J31: 590.89 | K31: SAR | L31: =IF(K31="USD",J31*$Q$7,J31) -> 590.89 | M31: 692 | N31: =IFERROR(L31/M31,"") -> 0.85388728 | O31: 73168 | P31: 47071 | R31: Meta delivery data | S31: 45245
B32: Bali Building_2023 | C32: 2023 | D32: Jul 2023 | E32: Jul 2023 | F32: 1 | G32: Nomuhub ad account | H32: Inactive | I32: Custom Conversion | J32: 293.26 | K32: SAR | L32: =IF(K32="USD",J32*$Q$7,J32) -> 293.26 | M32: 418 | N32: =IFERROR(L32/M32,"") -> 0.70157895 | O32: 76694 | P32: 50306 | R32: Meta delivery data | S32: 45058
B33: Zanzibar Teaching_2023 | C33: 2023 | D33: Purged by Meta | E33: Purged by Meta | G33: Nomuhub ad account | H33: Inactive | I33: No delivery | J33: 0 | K33: SAR | L33: =IF(K33="USD",J33*$Q$7,J33) -> 0 | N33: =IFERROR(L33/M33,"") | R33: Ran before Jul 2023, figures purged | S33: not in master file
B34: Kenya_Safari_2023 | C34: 2023 | D34: Purged by Meta | E34: Purged by Meta | G34: Nomuhub ad account | H34: Inactive | I34: No delivery | J34: 0 | K34: SAR | L34: =IF(K34="USD",J34*$Q$7,J34) -> 0 | N34: =IFERROR(L34/M34,"") | R34: Ran before Jul 2023, figures purged | S34: not in master file
B35: Explore_Trips_2023 | C35: 2023 | D35: Purged by Meta | E35: Purged by Meta | G35: Nomuhub ad account | H35: Inactive | I35: No delivery | J35: 0 | K35: SAR | L35: =IF(K35="USD",J35*$Q$7,J35) -> 0 | N35: =IFERROR(L35/M35,"") | R35: Ran before Jul 2023, figures purged | S35: not in master file
B36: Winter_2023 | C36: 2023 | D36: Purged by Meta | E36: Purged by Meta | G36: Nomuhub ad account | H36: Inactive | I36: No delivery | J36: 0 | K36: SAR | L36: =IF(K36="USD",J36*$Q$7,J36) -> 0 | N36: =IFERROR(L36/M36,"") | R36: Ran before Jul 2023, figures purged | S36: not in master file
B37: Welness Trip 2023 | C37: 2023 | D37: Purged by Meta | E37: Purged by Meta | G37: Nomuhub ad account | H37: Inactive | I37: No delivery | J37: 0 | K37: SAR | L37: =IF(K37="USD",J37*$Q$7,J37) -> 0 | N37: =IFERROR(L37/M37,"") | R37: Ran before Jul 2023, figures purged | S37: not in master file
B38: August 2023 Sales Campaign Campaign | C38: 2023 | D38: Purged by Meta | E38: Purged by Meta | G38: Nomuhub ad account | H38: Archived | I38: No delivery | J38: 0 | K38: SAR | L38: =IF(K38="USD",J38*$Q$7,J38) -> 0 | N38: =IFERROR(L38/M38,"") | R38: Ran before Jul 2023, figures purged | S38: not in master file
B39: Bali MSG Build june | C39: 2024 | D39: May 2024 | E39: Jul 2024 | F39: 3 | G39: Nomuhub ad account | H39: Inactive | I39: Messages | J39: 10785.96 | K39: SAR | L39: =IF(K39="USD",J39*$Q$7,J39) -> 10785.96 | M39: 836 | N39: =IFERROR(L39/M39,"") -> 12.901866 | O39: 316806 | P39: 141359 | R39: Meta delivery data | S39: 45442
B40: Bali Wellness Dec | C40: 2024 | D40: Oct 2024 | E40: Dec 2024 | F40: 3 | G40: Nomuhub ad account | H40: Inactive | I40: Messages | J40: 8049.83 | K40: SAR | L40: =IF(K40="USD",J40*$Q$7,J40) -> 8049.83 | M40: 463 | N40: =IFERROR(L40/M40,"") -> 17.386242 | O40: 145774 | P40: 80505 | R40: Meta delivery data | S40: 45589
B41: ZNZ Explore MSG | C41: 2024 | D41: Oct 2024 | E41: Nov 2024 | F41: 2 | G41: Nomuhub ad account | H41: Inactive | I41: Messages | J41: 7178.6 | K41: SAR | L41: =IF(K41="USD",J41*$Q$7,J41) -> 7178.6 | M41: 296 | N41: =IFERROR(L41/M41,"") -> 24.252027 | O41: 158608 | P41: 88287 | R41: Meta delivery data | S41: 45584
B42: Vietnam MSG | C42: 2024 | D42: Jul 2024 | E42: Sep 2024 | F42: 3 | G42: Nomuhub ad account | H42: Inactive | I42: Messages | J42: 6792.49 | K42: SAR | L42: =IF(K42="USD",J42*$Q$7,J42) -> 6792.49 | M42: 259 | N42: =IFERROR(L42/M42,"") -> 26.22583 | O42: 118823 | P42: 54057 | R42: Meta delivery data | S42: 45490
B43: Bali_Leads_2023 | C43: 2024 | D43: Jan 2024 | E43: Feb 2024 | F43: 2 | G43: Nomuhub ad account | H43: Inactive | I43: Custom Conversion | J43: 6696.47 | K43: SAR | L43: =IF(K43="USD",J43*$Q$7,J43) -> 6696.47 | M43: 77357 | N43: =IFERROR(L43/M43,"") -> 0.086565792 | O43: 4535858 | P43: 1315386 | R43: Meta delivery data | S43: 45252
...
